Workbook

Sheet VAT declaration 
D2: CỘNG HÒA XÃ HỘI CHỦ NGHĨA VIỆT NAM | J2: Mẫu số: 01/GTGT (Ban hành kèm theo Thông tư số 26/2015/TT-BTC ngày 27/02/2015 của Bộ Tài chính)
D3: Độc lập-Tự do-Hạnh phúc
F5: TỜ KHAI THUẾ GIÁ TRỊ GIA TĂNG (MẫU SỐ 01/GTGT)
F6: [01] Kỳ tính thuế: Quý 3 năm 2025
D7: [02] Lần đầu | E7: X | G7: [03] Bổ sung lần thứ: [ ]
B9: [04] Tên người nộp thu : CÔNG TY TNHH CRABI
B10: [05] Mã số thuế: 0319154011
B11: [06] Địa chỉ: 9 Đường Số 6, Phường Bình Tân
B12: [07] Quận/Huyện: | H12: [08] Tỉnh/Thành phố: HCM
B13: [09] Tel: | F13: [10] Fax: | H13: [11] Email:
I14: Unit: VND
A15: No. | B15: Chỉ tiêu | H15: Giá trị HHDV (chưa có thuế GTGT) | J15: Thuế GTGT
A16: A | B16: Không phát sinh hoạt động mua, bán trong kỳ (đánh dấu "X") | G16: [21]
A17: B | B17: B Thuế GTGT còn được khấu trừ kỳ trước chuyển sang | J17: [22]
A18: C | B18: Kê khai thuế GTGT phải nộp Ngân sách nhà nước
A19: 1 | B19: Hàng hoá, dịch vụ (HHDV) mua vào trong kỳ | H19: [23] | I19: ='02 GTGT đầu vào'!J30 -> 32937804 | J19: [24] | K19: ='02 GTGT đầu vào'!L30 -> 2679316 | L19: 32937804
A20: 2 | B20: Tổng số thuế GTGT được khấu trừ kỳ này | J20: [25] | K20: ='02 GTGT đầu vào'!M30 -> 2679316
A21: II | B21: Hàng hoá, dịch vụ bán ra trong kỳ
A22: 1 | B22: Hàng hóa, dịch vụ bán ra không chịu thuế GTGT | H22: [26]
A23: 2 | B23: Hàng hóa, dịch vụ bán ra chịu thuế GTGT ([27]=[29]+[30]+[32]+[32a]; [28]=[31]+[33]) | H23: [27] | I23: =I24+I25+I26 -> 0 | J23: [28] | K23: =K25+K26 -> 0
A24: a | B24: Hàng hoá, dịch vụ bán ra chịu thuế suất 0% | H24: [29] | I24: ='01 GTGT bán ra'!J17 -> 0
A25: b | B25: Hàng hoá, dịch vụ bán ra chịu thuế suất 5% | H25: [30] | J25: [31]
A26: c | B26: Hàng hoá, dịch vụ bán ra chịu thuế suất 10% | H26: [32] | I26: ='01 GTGT bán ra'!J24 -> 0 | J26: [33] | K26: ='01 GTGT bán ra'!K24 -> 0
A27: 3 | B27: Tổng doanh thu và thuế GTGT của HHDV bán ra ([34]=[26]+[27]; [35]=[28]) | H27: [34] | I27: =I22+I23 -> 0 | J27: [35] | K27: =K23 -> 0
A28: III | B28: Thuế GTGT phát sinh trong kỳ ([36]=[35]-[25]) | J28: [36] | K28: =K27-K20 -> -2679316
A29: IV | B29: Điều chỉnh tăng, giảm thuế GTGT còn được khấu trừ của các kỳ trước | K29: 0
A30: a | B30: Điều chỉnh giảm | J30: [37]
A31: b | B31: Điều chỉnh tăng | J31: [38]
A32: V | B32: Thuế GTGT đã nộp ở địa phương khác của hoạt động kinh doanh xây dựng, lắp đặt, bán hàng, bất động sản ngoại tỉnh | J32: [39]
A33: VI | B33: Xác định nghĩa vụ thuế GTGT phải nộp trong kỳ:
A34: 1 | B34: Thuế GTGT phải nộp của hoạt động sản xuất kinh doanh trong kỳ ([40a]=[36]-[22]+[37]-[38] - [39]≥ 0) | J34: [40a] | K34: =IF(K28-K17+K30-K31-K32>0,K28-K17+K30-K31-K32,0) -> 0
A35: 2 | B35: Thuế GTGT mua vào của dự án đầu tư được bù trừ với thuế GTGT còn phải nộp của hoạt động sản xuất kinh doanh cùng kỳ tính thuế | J35: [40b]
A36: 3 | B36: Thuế GTGT còn phải nộp trong kỳ ([40]=[40a]-[40b]) | J36: [40] | K36: =K34-K35 -> 0
A37: 4 | B37: Thuế GTGT chưa khấu trừ hết kỳ này (nếu [41]=[36]-[22]+[37]-[38]-[39] < 0) | J37: [41] | K37: =-IF(K28-K17+K30-K31-K32<0,K28-K17+K30-K31-K32,0) -> 2679316
A38: 4.1 | B38: Tổng số thuế GTGT đề nghị hoàn | J38: [42]
A39: 4.2 | B39: Thuế GTGT còn được khấu trừ chuyển kỳ sau ([43]=[41]-[42]) | J39: [43] | K39: =K37-K38 -> 2679316
A42: Tôi cam đoan số liệu khai trên là đúng và chịu trách nhiệm trước pháp luật về những số liệu đã khai./...
H43: HCMC, | I43: =TODAY() -> 46131
G44: Authorized representative of enterprise
G45: Signed and sealed

Sheet 02 GTGT đầu vào
B2: [04] Tên người nộp thuế: CÔNG TY TNHH SAIGON HANGUL SCHOOL
B3: [05] Mã số thuế: 0316326456
B4: MST:
F6: BẢNG KÊ HOÁ ĐƠN, CHỨNG TỪ HÀNG HOÁ, DỊCH VỤ MUA VÀO Q1/2022
F7: LIST OF VAT input INVOICE IN Q4/2022
B10: Unit: VND
B11: STT No. | C11: Hóa đơn/Invoice | G11: Tên người bán Suppliers | H11: Mã số thuế người bán Tax code | I11: Mặt hàng Goods | J11: Doanh số mua chưa có thuế Amount | K11: Thuế suất Tax | L11: Tiền thuế VAT amount | N11: Tổng/ Total | O11: Ghi chú Notes
C13: Ký hiệu mẫu hóa đơn | D13: Ký hiệu hoá đơn | E13: Số hoá đơn Invoice No. | F13: Ngày HĐ Date | M13: Tiền thuế được khấu trừ
B14: [1] | C14: [2] | D14: [3] | E14: [4] | F14: [5] | G14: [6] | H14: [7] | I14: [8] | J14: [9] | K14: [10] | L14: [11] | O14: [12]
B15: 1. Hàng hóa, dịch vụ sử dụng cho hoạt động sản xuất kinh doanh đủ điều kiện khấu trừ thuế:
D16: C25MTT | E16: 45223 | F16: 23/09/2025 | G16: CÔNG TY CỔ PHẦN THƯƠNG MẠI CC | H16: 0317618571 | I16: Chi phí tiếp khách | J16: 38889 | K16: 0.079996914 | L16: 3111 | M16: =L16 -> 3111 | N16: =J16+L16 -> 42000 | O16: 0.079996914
D17: K25DAB | E17: 74099781 | F17: 16/09/2025 | G17: Tập đoàn Công nghiệp - Viễn thông Quân đội | H17: 0100109106 | I17: Phí dịch vụ viễn thông | J17: 109091 | K17: 0.099999083 | L17: 10909 | M17: =L17 -> 10909 | N17: =J17+L17 -> 120000 | O17: 0.099999083
D18: K25DAB | E18: 74101638 | F18: 16/09/2025 | G18: Tập đoàn Công nghiệp - Viễn thông Quân đội | H18: 0100109106 | I18: Phí dịch vụ viễn thông | J18: 109091 | K18: 0.099999083 | L18: 10909 | M18: =L18 -> 10909 | N18: =J18+L18 -> 120000 | O18: 0.099999083
D19: K25DAB | E19: 74998640 | F19: 20/09/2025 | G19: Tập đoàn Công nghiệp - Viễn thông Quân đội | H19: 0100109106 | I19: Phí dịch vụ viễn thông | J19: 2574545 | K19: 0.10000019 | L19: 257455 | M19: =L19 -> 257455 | N19: =J19+L19 -> 2832000 | O19: 0.10000019
D20: K25TVA | E20: 2630648 | F20: 15/09/2025 | G20: Viettel Hồ Chí Minh- Chi nhánh Tập đoàn Công nghiệp - Viễn thông Quân đội | H20: 0100109106-122 | I20: Phí dịch vụ viễn thông | J20: 389815 | K20: 0.079999487 | L20: 31185 | M20: =L20 -> 31185 | N20: =J20+L20 -> 421000 | O20: 0.079999487
D21: K25TVA | E21: 2639276 | F21: 16/09/2025 | G21: Viettel Hồ Chí Minh- Chi nhánh Tập đoàn Công nghiệp - Viễn thông Quân đội | H21: 0100109106-122 | I21: Phí dịch vụ viễn thông | J21: 54545 | K21: 0.10000917 | L21: 5455 | M21: =L21 -> 5455 | N21: =J21+L21 -> 60000 | O21: 0.10000917
D22: K25TVA | E22: 2639372 | F22: 16/09/2025 | G22: Viettel Hồ Chí Minh- Chi nhánh Tập đoàn Công nghiệp - Viễn thông Quân đội | H22: 0100109106-122 | I22: Phí dịch vụ viễn thông | J22: 54545 | K22: 0.10000917 | L22: 5455 | M22: =L22 -> 5455 | N22: =J22+L22 -> 60000 | O22: 0.10000917
D23: K25TVA | E23: 2684402 | F23: 20/09/2025 | G23: Viettel Hồ Chí Minh- Chi nhánh Tập đoàn Công nghiệp - Viễn thông Quân đội | H23: 0100109106-122 | I23: Phí dịch vụ viễn thông | J23: 272727 | K23: 0.1000011 | L23: 27273 | M23: =L23 -> 27273 | N23: =J23+L23 -> 300000 | O23: 0.1000011
D24: K25TAA | E24: 23161 | F24: 26/09/2025 | G24: CÔNG TY TNHH CHỢ TỐT | H24: 0312120782 | I24: Dịch vụ quảng cáo | J24: 200000 | K24: 0.08 | L24: 16000 | M24: =L24 -> 16000 | N24: =J24+L24 -> 216000 | O24: 0.08
D25: C25TAA | E25: 15599 | F25: 16/09/2025 | G25: Công ty Cổ phần GMO-Z.com RUNSYSTEM | H25: 0101659906 | I25: Lệ phí đăng ký và phí duy trì Domain Vn 1 năm | J25: 1329000 | K25: 0.065553047 | L25: 87120 | M25: =L25 -> 87120 | N25: =J25+L25 -> 1416120 | O25: 0.065553047
D26: C25TYY | E26: 505 | F26: 18/09/2025 | G26: CÔNG TY TNHH LEO ALUMINIUM PACKAGING | H26: 0317891997 | I26: Máy ép seal bán tự động | J26: 14305556 | K26: 0.079999966 | L26: 1144444 | M26: =L26 -> 1144444 | N26: =J26+L26 -> 15450000 | O26: 0.079999966
D27: C25TTM | E27: 15 | F27: 23/09/2025 | G27: CÔNG TY TNHH THƯƠNG MẠI DỊCH VỤ ROI BUILDER PARTNER | H27: 0318445025 | I27: Thanh toán tạm ứng đợt 1 theo hợp đồng | J27: 13500000 | K27: 0.08 | L27: 1080000 | M27: =L27 -> 1080000 | N27: =J27+L27 -> 14580000 | O27: 0.08
B30: Tổng/ Total | J30: =SUM(J16:J28) -> 32937804 | L30: =SUM(L16:L27) -> 2679316 | M30: =SUM(M16:M28) -> 2679316 | N30: =SUM(N16:N28) -> 35617120
B31: 2. Hàng hoá, dịch vụ không đủ điều kiện khấu trừ:
B33: Tổng/ Total
B34: 3. Hàng hoá, dịch vụ dùng chung cho SXKD chịu thuế và không chịu thuế đủ điều kiện khấu trừ thuế:
B36: Tổng/ Total
B37: 4. Hàng hóa, dịch vụ dùng cho dự án đầu tư đủ điều kiện được khấu trừ thuế (*):
B39: Tổng/ Total
B40: 5. Hàng hóa, dịch vụ không phải tổng hợp trên tờ khai 01/GTGT:
B42: Tổng/ Total
B44: Tổng giá trị HHDV mua vào phục vụ SXKD được khấu trừ thuế GTGT (*): | J44: =J30 -> 32937804 | K44: VND
B45: Tổng số thuế GTGT của HHDV mua vào đủ điều kiện được khấu trừ (**): | J45: =M30 -> 2679316 | K45: VND
B47: Tôi xin cam đoan số liệu trên là đúng và chịu trách nhiệm trước pháp luật về những số liệu đã khai./…
J48: Ngày tháng năm
B49: NHÂN VIÊN ĐẠI LÝ THUẾ | J49: NGƯỜI NỘP THUẾ hoặc
B50: Họ tên: | J50: ĐẠI DIỆN HỢP PHÁP CỦA NGƯỜI NỘP THUẾ
B51: Chứng chỉ hành nghề số: | J51: Ký tên, đóng dấu (ghi rõ họ tên và chức vụ)
B57: Ghi chú:
B58: - GTGT: Giá trị gia tăng
...

Sheet 01 GTGT bán ra
B2: [04] Tên người nộp thuế: CÔNG TY TNHH SAIGON HANGUL SCHOOL
B3: [05] Mã số thuế: 0316326456
B4: MST:
B6: BẢNG KÊ HÓA ĐƠN, CHỨNG TỪ HÀNG HÓA, DỊCH VỤ BÁN RA
B7: Quý 4/2022
M8: Đơn vị tiền: VND
B9: STT | C9: Hóa đơn, chứng từ bán ra | G9: Tên người mua | H9: Mã số thuế người mua | I9: Mặt hàng | J9: Doanh thu chưa có thuế GTGT | K9: Thuế GTGT | L9: Tổng tiền | M9: Ghi chú
C10: Mã hóa đơn | D10: Ký hiệu hóa đơn | E10: Số hóa đơn | F10: Ngày, tháng, năm lập hóa đơn
B11: (1) | C11: (2) | E11: (3) | F11: (4) | G11: (5) | H11: (6) | I11: (7) | J11: (8) | K11: (9) | M11: (10)
B12: 1. Hàng hóa, dịch vụ không chịu thuế giá trị gia tăng (GTGT):
B14: Tổng
B15: 2. Hàng hóa, dịch vụ chịu thuế suất thuế GTGT 0%:
B17: Tổng | L17: =SUM(L16) -> 0
B18: 3. Hàng hóa, dịch vụ chịu thuế suất thuế GTGT 5%:
B20: Tổng
B21: 4. Hàng hóa, dịch vụ chịu thuế suất thuế GTGT 10%:
B22: 1 | L22: =J22+K22 -> 0
B23: 2 | L23: =J23+K23 -> 0
J24: =SUM(J22:J23) -> 0 | K24: =SUM(K22:K23) -> 0 | L24: =SUM(L22:L23) -> 0
B25: 5. Hàng hóa, dịch vụ không phải tổng hợp lên tờ khai 01 GTGT:
B27: Tổng
B29: Tổng giá trị HHDV bán ra (*): | J29: =+L24 -> 0 | K29: VND
B30: Tổng giá trị HHDV chịu thuế GTGT (**): | J30: =+J24 -> 0 | K30: VND
B31: Tổng số thuế GTGT của HHDV bán ra: (***): | J31: =+K24 -> 0 | K31: VND
B33: Tôi xin cam đoan số liệu trên là đúng và chịu trách nhiệm trước pháp luật về những số liệu đã khai./…
B35: NHÂN VIÊN ĐẠI LÝ THUẾ | I35: Ngày tháng năm
B36: Họ tên: | I36: NGƯỜI NỘP THUẾ hoặc
B37: Chứng chỉ hành nghề số: | I37: ĐẠI DIỆN HỢP PHÁP CỦA NGƯỜI NỘP THUẾ
I38: Ký tên, đóng dấu (ghi rõ họ tên và chức vụ)
B44: Ghi chú:
B45: - GTGT: Giá trị gia tăng
B46: - HHDV: Hàng hóa dịch vụ
B47: (*) Tổng giá trị HHDV bán ra là tổng số liệu cột 8 của các dòng tổng 1, 2, 3, 4
B48: (*) Tổng giá trị HHDV chịu thuế GTGT là tổng số liệu cột 8 của các dòng tổng 2, 3, 4
B49: (*) Tổng số thuế GTGT của HHDV bán ra là tổng số liệu cột 9 của các dòng tổng 2, 3, 4
